{"name": "insights.specs.Specs.rhsm_log", "exec_time": 0.00017213821411132812, "errors": ["Traceback (most recent call last):\n  File \"/var/lib/insights/newest.egg/insights/core/serde.py\", line 191, in dehydrate\n    doc[\"results\"] = marshal(value, root=self.data, pool=self.pool)\n  File \"/var/lib/insights/newest.egg/insights/core/serde.py\", line 106, in marshal\n    return f(v)\n  File \"/var/lib/insights/newest.egg/insights/core/serde.py\", line 85, in serialize\n    \"object\": to_dict(obj, root=root),\n  File \"/var/lib/insights/newest.egg/insights/core/spec_factory.py\", line 1036, in serialize_text_file_provider\n    rc = obj.write(dst)\n  File \"/var/lib/insights/newest.egg/insights/core/spec_factory.py\", line 287, in write\n    p.write(dst)\n  File \"/var/lib/insights/newest.egg/insights/util/subproc.py\", line 155, in write\n    six.reraise(be.__class__, be, sys.exc_info()[2])\n  File \"/usr/lib/python3.6/site-packages/six.py\", line 693, in reraise\n    raise value\n  File \"/var/lib/insights/newest.egg/insights/util/subproc.py\", line 151, in write\n    raise CalledProcessError(rc, self.cmds[0], \"\")\ninsights.util.subproc.CalledProcessError: (1, ['grep', '-F', \"KeyError: 'config.network.dnsConfig.hostName'\\nValidation failed: Name is invalid\\nvirt.host_type=hyperv, virt.uuid=Not Settable\", '/var/log/rhsm/rhsm.log'], '')\n"], "results": null, "ser_time": 0.003972530364990234}